#### [promise](https://es6.ruanyifeng.com/#docs/promise)

所谓`Promise`，简单说就是一个容器，里面保存着某个未来才会结束的事件（通常是一个异步操作）的结果。从语法上说，`Promise`是一个对象，从它可以获取异步操作的消息。



`Promise`对象有以下两个特点。

1. 对象的状态不受外界影响。`Promise`对象代表一个异步操作，有三种状态：`pending`（进行中）、`fulfilled`（已成功）和`rejected `（已失败）。只有异步操作的结果，可以决定当前是哪一种状态，任何其他操作都无法改变这个状态。这也是`Promise`这个名字的由来，它的英语意思就是“承诺”，表示其他手段无法改变。

2. 一旦状态改变，就不会再变，任何时候都可以得到这个结果。`Promise`对象的状态改变，只有两种可能：从`pending`变为`fulfilled`和从`pending`变为`rejected`。只要这两种情况发生，状态就凝固了，不会再变了，会一直保持这个结果，这时就称为` resolved`（已定型）。如果改变已经发生了，你再对`Promise`对象添加回调函数，也会立即得到这个结果。这与事件`（Event）`完全不同，事件的特点是，如果你错过了它，再去监听，是得不到结果的。

**注意，为了行文方便，本章后面的`resolved`统一只指`fulfilled`状态，不包含`rejected`状态。*



有了`Promise`对象，就可以将异步操作以同步操作的流程表达出来，避免了层层嵌套的回调函数。此外，`Promise`对象提供统一的接口，使得控制异步操作更加容易。

###### Promise 基本使用

```javascript
 const promise = new Promise(function(resolve, reject) {
  // ... some code
  if (/* 异步操作成功 */){
   resolve(value);
  } else {
   reject(error);
  }
 });
```

`Promise`构造函数接受一个函数作为参数，该函数的两个参数分别是`resolve`和`reject`。它们是两个函数，由 JavaScript 引擎提供，不用自己部署。

`resolve`函数的作用是，将`Promise`对象的状态从“未完成”变为“成功”（即从 pending 变为 resolved），在异步操作成功时调用，并将异步操作的结果，作为参数传递出去；`reject`函数的作用是，将`Promise`对象的状态从“未完成”变为“失败”（即从 pending 变为 rejected），在异步操作失败时调用，并将异步操作报出的错误，作为参数传递出去。

`Promise`实例生成以后，可以用`then`方法分别指定`resolved`状态和`rejected`状态的回调函数。

```javascript
promise.then(function(value) {
  // success
}, function(error) {
  // failure
});
```

`then`方法可以接受两个回调函数作为参数。第一个回调函数是`Promise`对象的状态变为`resolved`时调用，第二个回调函数是`Promise`对象的状态变为`rejected`时调用。这两个函数都是可选的，不一定要提供。它们都接受`Promise`对象传出的值作为参数。

下面是一个`Promise`对象的简单例子。

```javascript
function timeout(ms) {
  return new Promise((resolve, reject) => {
    setTimeout(resolve, ms, 'done');
  });
}

timeout(100).then((value) => {
  console.log(value);
});
```

上面代码中，`timeout`方法返回一个`Promise`实例，表示一段时间以后才会发生的结果。过了指定的时间（`ms`参数）以后，`Promise`实例的状态变为`resolved`，就会触发`then`方法绑定的回调函数。

```java
let promise = new Promise(function(resolve, reject) {
  console.log('Promise');
  resolve();
});

promise.then(function() {
  console.log('resolved.');
});

console.log('Hi!');

// Promise
// Hi!
// resolved
```

上面代码中，Promise 新建后立即执行，所以首先输出的是`Promise`。然后，`then`方法指定的回调函数，将在当前脚本所有同步任务执行完才会执行，所以`resolved`最后输出。

下面是异步加载图片的例子。

```javascript
function loadImageAsync(url) {
  return new Promise(function(resolve, reject) {
    const image = new Image();

    image.onload = function() {
      resolve(image);
    };

    image.onerror = function() {
      reject(new Error('Could not load image at ' + url));
    };

    image.src = url;
  });
}
```

上面代码中，使用`Promise`包装了一个图片加载的异步操作。如果加载成功，就调用`resolve`方法，否则就调用`reject`方法。

下面是一个用`Promise`对象实现的 Ajax 操作的例子。

```javascript
const getJSON = function(url) {
  const promise = new Promise(function(resolve, reject){
    const handler = function() {
      if (this.readyState !== 4) {
        return;
      }
      if (this.status === 200) {
        resolve(this.response);
      } else {
        reject(new Error(this.statusText));
      }
    };
    const client = new XMLHttpRequest();
    client.open("GET", url);
    client.onreadystatechange = handler;
    client.responseType = "json";
    client.setRequestHeader("Accept", "application/json");
    client.send();

  });

  return promise;
};

getJSON("/posts.json").then(function(json) {
  console.log('Contents: ' + json);
}, function(error) {
  console.error('出错了', error);
});
```

上面代码中，`getJSON`是对 XMLHttpRequest 对象的封装，用于发出一个针对 JSON 数据的 HTTP 请求，并且返回一个`Promise`对象。需要注意的是，在`getJSON`内部，`resolve`函数和`reject`函数调用时，都带有参数。

**如果调用`resolve`函数和`reject`函数时带有参数，那么它们的参数会被传递给回调函数。`reject`函数的参数通常是`Error`对象的实例，表示抛出的错误；**

**`resolve`函数的参数除了正常的值以外，还可能是另一个 Promise 实例，比如像下面这样。**

```javascript
const p1 = new Promise(function (resolve, reject) {
  // ...
});

const p2 = new Promise(function (resolve, reject) {
  // ...
  resolve(p1);
})
```

注意，这时`p1`的状态就会传递给`p2`，也就是说，`p1`的状态决定了`p2`的状态。如果`p1`的状态是`pending`，那么`p2`的回调函数就会等待`p1`的状态改变；如果`p1`的状态已经是`resolved`或者`rejected`，那么`p2`的回调函数将会立刻执行。

```javascript
const p1 = new Promise(function (resolve, reject) {
  setTimeout(() => reject(new Error('fail')), 3000)
})

const p2 = new Promise(function (resolve, reject) {
  setTimeout(() => resolve(p1), 1000)
})

p2
  .then(result => console.log(result))
  .catch(error => console.log(error))
// Error: fail
```

上面代码中，`p1`是一个 Promise，3 秒之后变为`rejected`。`p2`的状态在 1 秒之后改变，`resolve`方法返回的是`p1`。由于`p2`返回的是另一个 Promise，导致`p2`自己的状态无效了，由`p1`的状态决定`p2`的状态。所以，后面的`then`语句都变成针对后者（`p1`）。又过了 2 秒，`p1`变为`rejected`，导致触发`catch`方法指定的回调函数。

注意，调用`resolve`或`reject`并不会终结 Promise 的参数函数的执行。

```javascript
new Promise((resolve, reject) => {
  resolve(1);
  console.log(2);
}).then(r => {
  console.log(r);
});
// 2
// 1
```

上面代码中，调用`resolve(1)`以后，后面的`console.log(2)`还是会执行，并且会首先打印出来。这是因为立即 resolved 的 Promise 是在本轮事件循环的末尾执行，总是晚于本轮循环的同步任务。

一般来说，调用`resolve`或`reject`以后，Promise 的使命就完成了，后继操作应该放到`then`方法里面，而不应该直接写在`resolve`或`reject`的后面。所以，最好在它们前面加上`return`语句，这样就不会有意外。

```javascript
new Promise((resolve, reject) => {
  return resolve(1);
  // 后面的语句不会执行
  console.log(2);
})
```

##### Promise.prototype.then()

`Promise` 实例具有`then`方法，也就是说，`then`方法是定义在原型对象`Promise.prototype`上的。它的作用是为 `Promise` 实例添加状态改变时的回调函数。前面说过，`then`方法的第一个参数是`resolved`状态的回调函数，第二个参数是`rejected`状态的回调函数，它们都是可选的。

**`then`方法返回的是一个新的`Promise`实例（注意，不是原来那个`Promise`实例）。因此可以采用链式写法，即`then`方法后面再调用另一个`then`方法。**

```javascript
getJSON("/posts.json").then(function(json) {
  return json.post;
}).then(function(post) {
  // ...
});
```

上面的代码使用`then`方法，依次指定了两个回调函数。第一个回调函数完成以后，会将返回结果作为参数，传入第二个回调函数。

采用链式的`then`，可以指定一组按照次序调用的回调函数。这时，前一个回调函数，有可能返回的还是一个`Promise`对象（即有异步操作），这时后一个回调函数，就会等待该`Promise`对象的状态发生变化，才会被调用。

```javascript
getJSON("/post/1.json").then(function(post) {
  return getJSON(post.commentURL);
}).then(function (comments) {
  console.log("resolved: ", comments);
}, function (err){
  console.log("rejected: ", err);
});
```



##### Promise.prototype.catch()

`Promise.prototype.catch()`方法是`.then(null, rejection)`或`.then(undefined, rejection)`的别名，用于指定发生错误时的回调函数。

```javascript
getJSON('/posts.json').then(function(posts) {
  // ...
}).catch(function(error) {
  // 处理 getJSON 和 前一个回调函数运行时发生的错误
  console.log('发生错误！', error);
});
```

上面代码中，`getJSON()`方法返回一个 Promise 对象，如果该对象状态变为`resolved`，则会调用`then()`方法指定的回调函数；如果异步操作抛出错误，状态就会变为`rejected`，就会调用`catch()`方法指定的回调函数，处理这个错误。另外，`then()`方法指定的回调函数，如果运行中抛出错误，也会被`catch()`方法捕获。

```javascript
p.then((val) => console.log('fulfilled:', val))
  .catch((err) => console.log('rejected', err));

// 等同于
p.then((val) => console.log('fulfilled:', val))
  .then(null, (err) => console.log("rejected:", err));


-----

const promise = new Promise(function(resolve, reject) {
  throw new Error('test');
});
promise.catch(function(error) {
  console.log(error);
});
// Error: test
```

上面代码中，`promise`抛出一个错误，就被`catch()`方法指定的回调函数捕获。注意，上面的写法与下面两种写法是等价的。

```javascript
// 写法一
const promise = new Promise(function(resolve, reject) {
  try {
    throw new Error('test');
  } catch(e) {
    reject(e);
  }
});
promise.catch(function(error) {
  console.log(error);
});

// 写法二
const promise = new Promise(function(resolve, reject) {
  reject(new Error('test'));
});
promise.catch(function(error) {
  console.log(error);
});
```

**比较上面两种写法，可以发现`reject()`方法的作用，等同于抛出错误。**

**如果 Promise 状态已经变成`resolved`，再抛出错误是无效的。**

```javascript
const promise = new Promise(function(resolve, reject) {
  resolve('ok');
  throw new Error('test');
});
promise
  .then(function(value) { console.log(value) })
  .catch(function(error) { console.log(error) });
// ok
```

上面代码中，Promise 在`resolve`语句后面，再抛出错误，不会被捕获，等于没有抛出。因为 Promise 的状态一旦改变，就永久保持该状态，不会再变了。

Promise 对象的错误具有“冒泡”性质，会一直向后传递，直到被捕获为止。也就是说，错误总是会被下一个`catch`语句捕获。

```javascript
getJSON('/post/1.json').then(function(post) {
  return getJSON(post.commentURL);
}).then(function(comments) {
  // some code
}).catch(function(error) {
  // 处理前面三个Promise产生的错误
});
```

一般来说，不要在`then()`方法里面定义 Reject 状态的回调函数（即`then`的第二个参数），总是使用`catch`方法。

```javascript
// bad
promise
  .then(function(data) {
    // success
  }, function(err) {
    // error
  });

// good
promise
  .then(function(data) { //cb
    // success
  })
  .catch(function(err) {
    // error
  });
```

上面代码中，第二种写法要好于第一种写法，理由是第二种写法可以捕获前面`then`方法执行中的错误，也更接近同步的写法（`try/catch`）。**因此，建议总是使用`catch()`方法，而不使用`then()`方法的第二个参数。**

跟传统的`try/catch`代码块不同的是，如果没有使用`catch()`方法指定错误处理的回调函数，Promise 对象抛出的错误不会传递到外层代码，即不会有任何反应。

```javascript
const someAsyncThing = function() {
  return new Promise(function(resolve, reject) {
    // 下面一行会报错，因为x没有声明
    resolve(x + 2);
  });
};

someAsyncThing().then(function() {
  console.log('everything is great');
});

setTimeout(() => { console.log(123) }, 2000);
// Uncaught (in promise) ReferenceError: x is not defined
// 123
```

上面代码中，`someAsyncThing()`函数产生的 Promise 对象，内部有语法错误。浏览器运行到这一行，会打印出错误提示`ReferenceError: x is not defined`，但是不会退出进程、终止脚本执行，2 秒之后还是会输出`123`。这就是说，Promise 内部的错误不会影响到 Promise 外部的代码，通俗的说法就是“Promise 会吃掉错误”。

一般总是建议，Promise 对象后面要跟`catch()`方法，这样可以处理 Promise 内部发生的错误。`catch()`方法返回的还是一个 Promise 对象，因此后面还可以接着调用`then()`方法。

```javascript
const someAsyncThing = function() {
  return new Promise(function(resolve, reject) {
    // 下面一行会报错，因为x没有声明
    resolve(x + 2);
  });
};

someAsyncThing()
.catch(function(error) {
  console.log('oh no', error);
})
.then(function() {
  console.log('carry on');
});
// oh no [ReferenceError: x is not defined]
// carry on
```

上面代码运行完`catch()`方法指定的回调函数，会接着运行后面那个`then()`方法指定的回调函数。如果没有报错，则会跳过`catch()`方法。

```javascript
Promise.resolve()
.catch(function(error) {
  console.log('oh no', error);
})
.then(function() {
  console.log('carry on');
});
// carry on
```

上面的代码因为没有报错，跳过了`catch()`方法，直接执行后面的`then()`方法。此时，要是`then()`方法里面报错，就与前面的`catch()`无关了。

`catch()`方法之中，还能再抛出错误。

```javascript
const someAsyncThing = function() {
  return new Promise(function(resolve, reject) {
    // 下面一行会报错，因为x没有声明
    resolve(x + 2);
  });
};

someAsyncThing().then(function() {
  return someOtherAsyncThing();
}).catch(function(error) {
  console.log('oh no', error);
  // 下面一行会报错，因为 y 没有声明
  y + 2;
}).then(function() {
  console.log('carry on');
});
// oh no [ReferenceError: x is not defined]
```

上面代码中，`catch()`方法抛出一个错误，因为后面没有别的`catch()`方法了，导致这个错误不会被捕获，也不会传递到外层。如果改写一下，结果就不一样了。

```javascript
someAsyncThing().then(function() {
  return someOtherAsyncThing();
}).catch(function(error) {
  console.log('oh no', error);
  // 下面一行会报错，因为y没有声明
  y + 2;
}).catch(function(error) {
  console.log('carry on', error);
});
// oh no [ReferenceError: x is not defined]
// carry on [ReferenceError: y is not defined]
```

上面代码中，第二个`catch()`方法用来捕获前一个`catch()`方法抛出的错误。\

#### Promise.prototype.finally()

`finally()`方法用于指定不管 Promise 对象最后状态如何，都会执行的操作。该方法是 ES2018 引入标准的。

```javascript
promise
.then(result => {···})
.catch(error => {···})
.finally(() => {···});
```

上面代码中，不管`promise`最后的状态，在执行完`then`或`catch`指定的回调函数以后，都会执行`finally`方法指定的回调函数。

下面是一个例子，服务器使用 Promise 处理请求，然后使用`finally`方法关掉服务器。

```javascript
server.listen(port)
  .then(function () {
    // ...
  })
  .finally(server.stop);
```

`finally`方法的回调函数不接受任何参数，这意味着没有办法知道，前面的 Promise 状态到底是`fulfilled`还是`rejected`。这表明，`finally`方法里面的操作，应该是与状态无关的，不依赖于 Promise 的执行结果。

`finally`本质上是`then`方法的特例。

#### Promise.all()

---

[为什么要有 Async/await ?](https://codehhr.cn/2021/06/25/js/es7-async-await/)

Promise 虽然跳出了异步嵌套的怪圈 , 解决了回调地狱的问题 , 用链式表达更加清晰 , 但是我们也发现如果有大量的异步请求的时候 , 流程复杂的情况下 , 会发现充满了屏幕的 then , 看起来非常吃力 , 而 ES7 的 Async/Await 的出现就是为了解决这种复杂的情况



async 用于申明一个 function 是异步的 , 返回一个 promise 对象 , 而 await 可以认为是 async wait 的简写 , 等待一个异步方法执行完成 , async 必须声明的是一个 function , await 必须在声明的函数内部使用



ES7语法糖，基于Promise,处理异步任务更加方便, 具体来说是 `Promise.then` 的语法糖。



`await` 右侧的表达式一般为promise对象，但也可以是其他的值
如果表达式是promise对象，那么返回的是promise**成功**的值
如果是其他的值，直接将此值作为await的返回值（可以认为await 是失效了的，直接结果返回）



[文章](https://www.cnblogs.com/leungUwah/p/7932912.html)

async顾名思义是“异步”的意思，async用于声明一个函数是异步的。而await从字面意思上是“等待”的意思，就是用于等待异步完成。并且await只能在async函数中使用

通常async、await都是跟随Promise一起使用的。为什么这么说呢？因为async返回的都是一个Promise对象同时async适用于任何类型的函数上。这样await得到的就是一个Promise对象(如果不是Promise对象的话那async返回的是什么 就是什么)；

await得到Promise对象之后就等待Promise接下来的resolve或者reject。

来看一段简单的代码：

```javascript
async function testSync() {
     const response = await new Promise(resolve => {
         setTimeout(() => {
             resolve("async await test...");
          }, 1000);
     });
     console.log(response);
}
testSync();//async await test...
```

就这样一个简单的async、await异步就完成了。使用async、await完成异步操作代码可读与写法上更像是同步的，也更容易让人理解。

##  async、await串行并行处理

串行：等待前面一个await执行后接着执行下一个await，以此类推

```javascript
async function asyncAwaitFn(str) {
    return await new Promise((resolve, reject) => {
        setTimeout(() => {
            resolve(str)
        }, 1000);
    })
}

const serialFn = async () => { //串行执行
    console.time('serialFn')
    console.log(await asyncAwaitFn('string 1'));
    console.log(await asyncAwaitFn('string 2'));
    console.timeEnd('serialFn')
}

serialFn();
```

输出：

> string 1
> string 2
> serialFn: 2011.585205078125 ms

可以看到两个await串行执行的总耗时为两千多毫秒。



### 并行：将多个promise直接发起请求（先执行async所在函数），然后再进行await操作。

```javascript
async function asyncAwaitFn(str) {
    return await new Promise((resolve, reject) => {
        setTimeout(() => {
            resolve(str)
        }, 1000);
    })
}
const parallel = async () => { //并行执行
    console.time('parallel')
    const parallelOne = asyncAwaitFn('string 1');
    const parallelTwo = asyncAwaitFn('string 2')

    //直接打印
    console.log(await parallelOne)
    console.log(await parallelTwo)

    console.timeEnd('parallel')
}
parallel()
```

> string 1
> string 2
> parallel: 1008.758056640625 ms

## async、await错误处理

JavaScript异步请求肯定会有请求失败的情况，上面也说到了async返回的是一个Promise对象。既然是返回一个Promise对象的话那处理当异步请求发生错误的时候我们就要处理reject的状态了。

在Promise中当请求reject的时候我们可以使用catch。为了保持代码的健壮性使用async、**await的时候我们使用try catch来处理错误。**

```javascript
async function catchErr() {
    try {
        const errRes = await new Promise((resolve, reject) => {
            setTimeout(() => {
                reject("http error...");
            }, 1000);
            );
            //平常我们也可以在await请求成功后通过判断当前status是不是200来判断请求是否成功
            // console.log(errRes.status, errRes.statusText);
        } catch(err) {
            console.log(err);
        }
    }
}
    
catchErr(); //http error...
```

